Workbook

Sheet lista excel
A1: LISTA DE PRECIOS MAYORISTA (ULTIMA ACT. 28/04)
A3: ID | B3: MARCA | C3: LINEA | D3: CODIGO DE BARRA | E3: NOMBRE | F3: PRESENTACIONES | G3: PRECIO FINAL MAYORISTA
A4: 1096 | B4: BABYSEC | C4: BABYSEC ULTRASOFT | D4: =_xlfn.XLOOKUP(Tabla13[[#This Row],[ID]],BAJADA!$I:$I,BAJADA!$B:$B,"error",1) -> 7790250040880 | E4: BABYSEC ULTRASOFT PROMOPACK | F4: M68,G60,XG52,XXG50 | G4: =_xlfn.XLOOKUP(Tabla13[[#This Row],[ID]],BAJADA!$I:$I,BAJADA!$K:$K,"error",1) -> 11699
A5: 1089 | D5: =_xlfn.XLOOKUP(Tabla13[[#This Row],[ID]],BAJADA!$I:$I,BAJADA!$B:$B,"error",1) -> 7790250042082 | E5: BABYSEC ULTRASOFT HIPERPACK | F5: M48,G40,XG32,XXG30,XXXG28 | G5: =_xlfn.XLOOKUP(Tabla13[[#This Row],[ID]],BAJADA!$I:$I,BAJADA!$K:$K,"error",1) -> 8230
A6: 4416 | D6: =_xlfn.XLOOKUP(Tabla13[[#This Row],[ID]],BAJADA!$I:$I,BAJADA!$B:$B,"error",1) -> 7790250040798 | E6: BABYSEC ULTRASOFT REGULAR | F6: XXG8 | G6: =_xlfn.XLOOKUP(Tabla13[[#This Row],[ID]],BAJADA!$I:$I,BAJADA!$K:$K,"error",1) -> 2098.14
A7: 1100 | C7: BABYSEC PREMIUMSOFT | D7: =_xlfn.XLOOKUP(Tabla13[[#This Row],[ID]],BAJADA!$I:$I,BAJADA!$B:$B,"error",1) -> 7790250047247 | E7: BABYSEC PREMIUMSOFT JUMBO PACK | F7: G60,XG48,XXG44 | G7: =_xlfn.XLOOKUP(Tabla13[[#This Row],[ID]],BAJADA!$I:$I,BAJADA!$K:$K,"error",1) -> 14850
A8: 1731 | D8: =_xlfn.XLOOKUP(Tabla13[[#This Row],[ID]],BAJADA!$I:$I,BAJADA!$B:$B,"error",1) -> 7790250042822 | E8: BABYSEC PREMIUMSOFT HIPERPACK | F8: M48,G40,XG32,XXG30 | G8: =_xlfn.XLOOKUP(Tabla13[[#This Row],[ID]],BAJADA!$I:$I,BAJADA!$K:$K,"error",1) -> 9999
A9: 3753 | C9: BABYSEC PREMIUM (LINEA VIEJA) | D9: =_xlfn.XLOOKUP(Tabla13[[#This Row],[ID]],BAJADA!$I:$I,BAJADA!$B:$B,"error",1) -> 7790250047360 | E9: BABYSEC PREMIUM HIPER (HASTA AGOTAR STOCK) | F9: XG32 | G9: =_xlfn.XLOOKUP(Tabla13[[#This Row],[ID]],BAJADA!$I:$I,BAJADA!$K:$K,"error",1) -> 7890
A10: 2316 | D10: =_xlfn.XLOOKUP(Tabla13[[#This Row],[ID]],BAJADA!$I:$I,BAJADA!$B:$B,"error",1) -> 7790250042754 | E10: BABYSEC PREMIUM REGULAR | F10: P12 | G10: =_xlfn.XLOOKUP(Tabla13[[#This Row],[ID]],BAJADA!$I:$I,BAJADA!$K:$K,"error",1) -> 2571.492
A11: 4447 | C11: PREMIUM PANTS | D11: =_xlfn.XLOOKUP(Tabla13[[#This Row],[ID]],BAJADA!$I:$I,BAJADA!$B:$B,"error",1) -> 7896061999987 | E11: BABYSEC PREMIUM PANTS | F11: G28,XG22,XXG20 | G11: =_xlfn.XLOOKUP(Tabla13[[#This Row],[ID]],BAJADA!$I:$I,BAJADA!$K:$K,"error",1) -> 9140
A12: 3376 | C12: BABYSEC SUPER PREMIUM | D12: =_xlfn.XLOOKUP(Tabla13[[#This Row],[ID]],BAJADA!$I:$I,BAJADA!$B:$B,"error",1) -> 7790250042174 | E12: BABYSEC SUPER PREMIUM PROMOPACK | F12: G60,XG48,XXG44 | G12: =_xlfn.XLOOKUP(Tabla13[[#This Row],[ID]],BAJADA!$I:$I,BAJADA!$K:$K,"error",1) -> 18096.458
A13: 3378 | D13: =_xlfn.XLOOKUP(Tabla13[[#This Row],[ID]],BAJADA!$I:$I,BAJADA!$B:$B,"error",1) -> 7790250042181 | E13: BABYSEC SUPER PREMIUM HIPERPACK | F13: M48 | G13: =_xlfn.XLOOKUP(Tabla13[[#This Row],[ID]],BAJADA!$I:$I,BAJADA!$K:$K,"error",1) -> 11809.66
A14: 3379 | D14: =_xlfn.XLOOKUP(Tabla13[[#This Row],[ID]],BAJADA!$I:$I,BAJADA!$B:$B,"error",1) -> 7790250042198 | E14: BABYSEC SUPER PREMIUM PEQUEÑO | F14: P30 | G14: =_xlfn.XLOOKUP(Tabla13[[#This Row],[ID]],BAJADA!$I:$I,BAJADA!$K:$K,"error",1) -> 7875.89
A15: 4410 | D15: =_xlfn.XLOOKUP(Tabla13[[#This Row],[ID]],BAJADA!$I:$I,BAJADA!$B:$B,"error",1) -> 7759185010924 | E15: BABYSEC RECIEN NACIDO | F15: X20U | G15: =_xlfn.XLOOKUP(Tabla13[[#This Row],[ID]],BAJADA!$I:$I,BAJADA!$K:$K,"error",1) -> 6055.808
A16: 4312 | B16: PAÑAL NANO | C16: OFERTA TOTAL | E16: PAÑAL NANO AHORRO | F16: M62,G58,XG50,XXG44 | G16: =_xlfn.XLOOKUP(Tabla13[[#This Row],[ID]],BAJADA!$I:$I,BAJADA!$K:$K,"error",1) -> 8499
A17: 1132 | B17: DUFFY | C17: DUFFY COTTON | D17: =_xlfn.XLOOKUP(Tabla13[[#This Row],[ID]],BAJADA!$I:$I,BAJADA!$B:$B,"error",1) -> 7798350085428 | E17: DUFFY MEGA AHORRO | F17: M52,G48,XG44,XXG42 | G17: =_xlfn.XLOOKUP(Tabla13[[#This Row],[ID]],BAJADA!$I:$I,BAJADA!$K:$K,"error",1) -> 10690
A18: 1135 | D18: =_xlfn.XLOOKUP(Tabla13[[#This Row],[ID]],BAJADA!$I:$I,BAJADA!$B:$B,"error",1) -> 7798350082328 | E18: DUFFY COTTON | F18: P40,M36,G32,XG28,XXG26 | G18: =_xlfn.XLOOKUP(Tabla13[[#This Row],[ID]],BAJADA!$I:$I,BAJADA!$K:$K,"error",1) -> 6990
A19: 1503 | D19: =_xlfn.XLOOKUP(Tabla13[[#This Row],[ID]],BAJADA!$I:$I,BAJADA!$B:$B,"error",1) -> 7798350080218 | E19: DUFFY COTTON PEQ 30U | G19: =_xlfn.XLOOKUP(Tabla13[[#This Row],[ID]],BAJADA!$I:$I,BAJADA!$K:$K,"error",1) -> 3806.66
A20: 1305 | C20: DUFFY PREMIUM | D20: =_xlfn.XLOOKUP(Tabla13[[#This Row],[ID]],BAJADA!$I:$I,BAJADA!$B:$B,"error",1) -> 7798350080195 | E20: DUFFY PREMIUM | F20: P40,M40,G36,XG32,XXG30 | G20: =_xlfn.XLOOKUP(Tabla13[[#This Row],[ID]],BAJADA!$I:$I,BAJADA!$K:$K,"error",1) -> 7500
A21: 1784 | D21: =_xlfn.XLOOKUP(Tabla13[[#This Row],[ID]],BAJADA!$I:$I,BAJADA!$B:$B,"error",1) -> 7798350081017 | E21: DUFFY PREMIUM PEQ 30U | G21: =_xlfn.XLOOKUP(Tabla13[[#This Row],[ID]],BAJADA!$I:$I,BAJADA!$K:$K,"error",1) -> 5500
A22: 1082 | B22: ESTRELLA | D22: =_xlfn.XLOOKUP(Tabla13[[#This Row],[ID]],BAJADA!$I:$I,BAJADA!$B:$B,"error",1) -> 7790064004238 | E22: ESTRELLA HIPERPACK | F22: M44,G40,XG36,XXG34,J30 | G22: =_xlfn.XLOOKUP(Tabla13[[#This Row],[ID]],BAJADA!$I:$I,BAJADA!$K:$K,"error",1) -> 10900
A23: 1540 | D23: =_xlfn.XLOOKUP(Tabla13[[#This Row],[ID]],BAJADA!$I:$I,BAJADA!$B:$B,"error",1) -> 7790064005518 | E23: ESTRELLA SUPERPACK | F23: G60,XG52,XXG50 | G23: =_xlfn.XLOOKUP(Tabla13[[#This Row],[ID]],BAJADA!$I:$I,BAJADA!$K:$K,"error",1) -> 17100
A24: 1087 | D24: =_xlfn.XLOOKUP(Tabla13[[#This Row],[ID]],BAJADA!$I:$I,BAJADA!$B:$B,"error",1) -> 7790064104983 | E24: ESTRELLA SUPERPACK J50 | G24: =_xlfn.XLOOKUP(Tabla13[[#This Row],[ID]],BAJADA!$I:$I,BAJADA!$K:$K,"error",1) -> 17100
A25: 1042 | D25: =_xlfn.XLOOKUP(Tabla13[[#This Row],[ID]],BAJADA!$I:$I,BAJADA!$B:$B,"error",1) -> 7790064004023 | E25: ESTRELLA PEQ 30U | G25: =_xlfn.XLOOKUP(Tabla13[[#This Row],[ID]],BAJADA!$I:$I,BAJADA!$K:$K,"error",1) -> 7800
A26: 1056 | B26: HUGGIES | C26: SUPREME CARE | D26: =_xlfn.XLOOKUP(Tabla13[[#This Row],[ID]],BAJADA!$I:$I,BAJADA!$B:$B,"error",1) -> 7794626013348 | E26: HUGGIES SUPREME PROMO | F26: M68,G60,XG52,XXG50,XXXG48 | G26: =_xlfn.XLOOKUP(Tabla13[[#This Row],[ID]],BAJADA!$I:$I,BAJADA!$K:$K,"error",1) -> 22300
A27: 1036 | D27: =_xlfn.XLOOKUP(Tabla13[[#This Row],[ID]],BAJADA!$I:$I,BAJADA!$B:$B,"error",1) -> 7794626012419 | E27: HUGGIES SUPREME PEQ 50U | G27: =_xlfn.XLOOKUP(Tabla13[[#This Row],[ID]],BAJADA!$I:$I,BAJADA!$K:$K,"error",1) -> 17700
A28: 1555 | D28: =_xlfn.XLOOKUP(Tabla13[[#This Row],[ID]],BAJADA!$I:$I,BAJADA!$B:$B,"error",1) -> 7794626013362 | E28: HUGGIES SUPREME RN 34U | G28: =_xlfn.XLOOKUP(Tabla13[[#This Row],[ID]],BAJADA!$I:$I,BAJADA!$K:$K,"error",1) -> 13799
A29: 1064 | D29: =_xlfn.XLOOKUP(Tabla13[[#This Row],[ID]],BAJADA!$I:$I,BAJADA!$B:$B,"error",1) -> 7794626007149 | E29: HUGGIES SUPREME PREMATURO 30U | G29: =_xlfn.XLOOKUP(Tabla13[[#This Row],[ID]],BAJADA!$I:$I,BAJADA!$K:$K,"error",1) -> 9400.3569
A30: 1067 | C30: FLEXI COMFORT | D30: =_xlfn.XLOOKUP(Tabla13[[#This Row],[ID]],BAJADA!$I:$I,BAJADA!$B:$B,"error",1) -> 7794626012884 | E30: HUGGIES FLEXI PROMO | F30: M68,G60,XG52,XXG50,XXXG48 | G30: =_xlfn.XLOOKUP(Tabla13[[#This Row],[ID]],BAJADA!$I:$I,BAJADA!$K:$K,"error",1) -> 17790
A31: 1035 | D31: =_xlfn.XLOOKUP(Tabla13[[#This Row],[ID]],BAJADA!$I:$I,BAJADA!$B:$B,"error",1) -> 7794626012938 | E31: HUGGIES FLEXI PEQ 50U | G31: =_xlfn.XLOOKUP(Tabla13[[#This Row],[ID]],BAJADA!$I:$I,BAJADA!$K:$K,"error",1) -> 14900
A32: 1066 | D32: =_xlfn.XLOOKUP(Tabla13[[#This Row],[ID]],BAJADA!$I:$I,BAJADA!$B:$B,"error",1) -> 7794626012914 | E32: HUGGIES FLEXI RN 34U | G32: =_xlfn.XLOOKUP(Tabla13[[#This Row],[ID]],BAJADA!$I:$I,BAJADA!$K:$K,"error",1) -> 8999
A33: 1077 | C33: TRIPLE PROTECCION AMARILLOS | D33: =_xlfn.XLOOKUP(Tabla13[[#This Row],[ID]],BAJADA!$I:$I,BAJADA!$B:$B,"error",1) -> 7794626009983 | E33: HUGGIES AMARILLOS PROMO | F33: M68,G60,XG52,XXG50,XXXG48 | G33: =_xlfn.XLOOKUP(Tabla13[[#This Row],[ID]],BAJADA!$I:$I,BAJADA!$K:$K,"error",1) -> 15300
A34: 1073 | C34: PROTECT PLUS | D34: =_xlfn.XLOOKUP(Tabla13[[#This Row],[ID]],BAJADA!$I:$I,BAJADA!$B:$B,"error",1) -> 7794626011948 | E34: HUGGIES PROTECT PROMO | F34: M68,G60,XG52,XXG50,XXXG48 | G34: =_xlfn.XLOOKUP(Tabla13[[#This Row],[ID]],BAJADA!$I:$I,BAJADA!$K:$K,"error",1) -> 12000
A35: 2081 | D35: =_xlfn.XLOOKUP(Tabla13[[#This Row],[ID]],BAJADA!$I:$I,BAJADA!$B:$B,"error",1) -> 7794626013591 | E35: HUGGIES PROTECT PEQ 50U | G35: =_xlfn.XLOOKUP(Tabla13[[#This Row],[ID]],BAJADA!$I:$I,BAJADA!$K:$K,"error",1) -> 8800
A36: 1049 | D36: =_xlfn.XLOOKUP(Tabla13[[#This Row],[ID]],BAJADA!$I:$I,BAJADA!$B:$B,"error",1) -> 7794626999765 | E36: HUGGIES PROTECT REGULAR | F36: G8,XG8,XXG8 | G36: =_xlfn.XLOOKUP(Tabla13[[#This Row],[ID]],BAJADA!$I:$I,BAJADA!$K:$K,"error",1) -> 2301.42
A37: 1128 | C37: ULTRACOMFORT | D37: =_xlfn.XLOOKUP(Tabla13[[#This Row],[ID]],BAJADA!$I:$I,BAJADA!$B:$B,"error",1) -> 7794626013683 | E37: HUGGIES ULTRACOMFORT PROMO | F37: M68,G60,XG52,XXG50 | G37: =_xlfn.XLOOKUP(Tabla13[[#This Row],[ID]],BAJADA!$I:$I,BAJADA!$K:$K,"error",1) -> 19800
A38: 3330 | C38: PANTS | D38: =_xlfn.XLOOKUP(Tabla13[[#This Row],[ID]],BAJADA!$I:$I,BAJADA!$B:$B,"error",1) -> 7896007552719 | E38: HUGGIES PANTS NATURAL CARE | F38: XG56,XXG52 | G38: =_xlfn.XLOOKUP(Tabla13[[#This Row],[ID]],BAJADA!$I:$I,BAJADA!$K:$K,"error",1) -> 27834.453
A39: 1126 | B39: PAMPERS | C39: DELUXE | D39: =_xlfn.XLOOKUP(Tabla13[[#This Row],[ID]],BAJADA!$I:$I,BAJADA!$B:$B,"error",1) -> 7500435237574 | E39: PAMPERS DELUXE MES | F39: G110,XG96,XXG88 | G39: =_xlfn.XLOOKUP(Tabla13[[#This Row],[ID]],BAJADA!$I:$I,BAJADA!$K:$K,"error",1) -> 44600
A40: 1117 | D40: =_xlfn.XLOOKUP(Tabla13[[#This Row],[ID]],BAJADA!$I:$I,BAJADA!$B:$B,"error",1) -> 7500435237543 | E40: PAMPERS DELUXE PROMO | F40: M72,G72,XG58,XXG54 | G40: =_xlfn.XLOOKUP(Tabla13[[#This Row],[ID]],BAJADA!$I:$I,BAJADA!$K:$K,"error",1) -> 29400
A41: 1039 | D41: =_xlfn.XLOOKUP(Tabla13[[#This Row],[ID]],BAJADA!$I:$I,BAJADA!$B:$B,"error",1) -> 7500435237611 | E41: PAMPERS DELUXE PEQ. 36U | G41: =_xlfn.XLOOKUP(Tabla13[[#This Row],[ID]],BAJADA!$I:$I,BAJADA!$K:$K,"error",1) -> 15500
...

Sheet BAJADA
A1: Código Interno | B1: Código de Barras | C1: Producto | D1: Marca | E1: Categoría | F1: Neto | G1: Final | H1: Moneda | I1: id | J1: MAYORISTA (NETO) | K1: MAYORISTA (FINAL)
B2: 7798047032537 | C2: REPELENTE AEROSOL 911 150ML | D2: 911 | E2: PERFUMERIA | F2: 3206.6116 | G2: 3880 | H2: $ | I2: 3864 | J2: 2556.45 | K2: 3093.3045
B3: 7798047033114 | C3: REPELENTE AEROSOL 911 150ML | D3: 911 | E3: PERFUMERIA | F3: 3880 | G3: 3880 | H3: $ | I3: 5755 | J3: 2990 | K3: 2990
B4: 7790990002971 | C4: ACE 1400ML DOYPACK | D4: ACE | E4: LIMPIEZA | F4: 3504.1322 | G4: 4240 | H4: $ | I4: 5084 | J4: 3125 | K4: 3781.25
B5: 7790990002964 | C5: ACE DOYPACK 800ML CLASICO | D5: ACE | E5: LIMPIEZA | F5: 2239.6694 | G5: 2710 | H5: $ | I5: 5089 | J5: 1998.75 | K5: 2418.4875
B6: 7790990003008 | C6: ACE JAB LIQ 800ML BOT CLASICO | D6: ACE | E6: LIMPIEZA | F6: 2371.9008 | G6: 2870 | H6: $ | I6: 4597 | J6: 2117.5 | K6: 2562.175
B7: 7790990002926 | C7: ACE MATIC POLVO 800GRS | D7: ACE | E7: LIMPIEZA | F7: 2024.7934 | G7: 2450 | H7: $ | I7: 5646 | J7: 1803.75 | K7: 2182.5375
B8: 7790990002858 | C8: ACE PARA DILUIR 500ML BOTELLA | D8: ACE | E8: LIMPIEZA | F8: 5256.1983 | G8: 6360 | H8: $ | I8: 5012 | J8: 4687.5 | K8: 5671.875
B9: 7790990002957 | C9: ACE POLVO 3KG A MANO | D9: ACE | E9: LIMPIEZA | F9: 7454.5455 | G9: 9020 | H9: $ | I9: 5069 | J9: 6655 | K9: 8052.55
B10: 7790990002902 | C10: ACE POLVO 3KG MATIC | D10: ACE | E10: LIMPIEZA | F10: 7454.5455 | G10: 9020 | H10: $ | I10: 5068 | J10: 6655 | K10: 8052.55
B11: 7790990002933 | C11: ACE POLVO 400GRS LAV A MANO | D11: ACE | E11: LIMPIEZA | F11: 884.29752 | G11: 1070 | H11: $ | I11: 5088 | J11: 782.5 | K11: 946.825
B12: 7790990002919 | C12: ACE POLVO 400GRS MATIC | D12: ACE | E12: LIMPIEZA | F12: 884.29752 | G12: 1070 | H12: $ | I12: 5087 | J12: 782.5 | K12: 946.825
B13: 7790990002940 | C13: ACE POLVO LAV A MANO 800GRS | D13: ACE | E13: LIMPIEZA | F13: 2024.7934 | G13: 2450 | H13: $ | I13: 5647 | J13: 1803.75 | K13: 2182.5375
B14: 7796285288983 | C14: ADERMICINA ANTIARRUGA 90GR CREMA FACIAL | D14: ADERMICINA | E14: PERFUMERIA | F14: 2719.0083 | G14: 3290 | H14: $ | I14: 1859 | J14: 2080.35 | K14: 2517.2235
B15: 7796285289003 | C15: ADERMICINA HUMECTANTE 90GR CREMA FACIAL | D15: ADERMICINA | E15: PERFUMERIA | F15: 2719.0083 | G15: 3290 | H15: $ | I15: 1858 | J15: 2080.35 | K15: 2517.2235
... B592: 04849 | C592: ACOLCHADO DUMOY C/BOLSA MANIJA 2 1/2 ART | D592: BILBAO | E592: BLANQUERIA | F592: 26900 | G592: 26900 | H592: $ | I592: 4849 | J592: 21275 | K592: 21275
A593: 4205 | B593: 8537543870408 | C593: ALFOMBRA BAÑO ANTIDESLIZANTE PVC | D593: BILBAO | E593: BLANQUERIA | F593: 4550 | G593: 4550 | H593: $ | I593: 2392 | J593: 3737.5 | K593: 3737.5
B594: 736684277475 | C594: ALFOMBRA CRUDA ESTAMPADA | D594: BILBAO | E594: BLANQUERIA | F594: 2350 | G594: 2350 | H594: $ | I594: 2391 | J594: 2012.4 | K594: 2012.4
B595: 7586475664129 | C595: ALFOMBRA INFANTIL RECTANGULAR Y FORMAS | D595: BILBAO | E595: BLANQUERIA | F595: 6160 | G595: 6160 | H595: $ | I595: 3882 | J595: 5060 | K595: 5060
B596: 02398 | C596: ALFOMBRA SHAGGY RECTANGULAR/REDONDA | D596: BILBAO | E596: BLANQUERIA | F596: 5603.3058 | G596: 6780 | H596: $ | I596: 2398 | J596: 4600 | K596: 5566
B597: 7798156621349 | C597: ALMOHADA 70X40 PREMIUM DORMICLASS | D597: BILBAO | E597: BLANQUERIA | F597: 16440 | G597: 16440 | H597: $ | I597: 4061 | J597: 13501 | K597: 13501
B598: 7798156621325 | C598: ALMOHADA DORMICLASS CLASICA 70 X 40 | D598: BILBAO | E598: BLANQUERIA | F598: 11880 | G598: 11880 | H598: $ | I598: 4214 | J598: 9757.75 | K598: 9757.75
B599: 7798156621431 | C599: ALMOHADA DORMICLASS VISCO INTELIGENTE | D599: BILBAO | E599: BLANQUERIA | F599: 29450 | G599: 29450 | H599: $ | I599: 5045 | J599: 26047.5 | K599: 26047.5
B600: 04411 | C600: ALMOHADA DUMOY INICIA | D600: BILBAO | E600: BLANQUERIA | F600: 6300 | G600: 6300 | H600: $ | I600: 4411 | J600: 5175 | K600: 5175
B601: 03885 | C601: ALMOHADA VISCOELASTICA DUMOY | D601: BILBAO | E601: BLANQUERIA | F601: 18300 | G601: 18300 | H601: $ | I601: 3885 | J601: 15582.5 | K601: 15582.5
B602: 03868 | C602: BOMBACHA CULOTE DOCENA COD 403 | D602: BILBAO | E602: BLANQUERIA | F602: 17900 | G602: 17900 | H602: $ | I602: 3868 | J602: 15237.5 | K602: 15237.5
B603: 03557 | C603: CAMPERA IMPORTADA INFLABLE ADULTO | D603: BILBAO | E603: BLANQUERIA | F603: 16140 | G603: 16140 | H603: $ | I603: 3557 | J603: 14999 | K603: 14999
B604: 03095 | C604: CAMPERA NIÑO/A INFLABLE | D604: BILBAO | E604: BLANQUERIA | F604: 8400 | G604: 8400 | H604: $ | I604: 3095 | J604: 6900 | K604: 6900
B605: 05044 | C605: CORTINA AMBIENTE TROPICAL C/GOBELINO | D605: BILBAO | E605: BLANQUERIA | F605: 16300 | G605: 16300 | H605: $ | I605: 5044 | J605: 13363 | K605: 13363
... B635: f742/1 | C635: PACK FUNDAS MULTIAGUJAS LOUISIANA | D635: BILBAO | E635: BLANQUERIA | F635: 7660 | G635: 7660 | H635: $ | I635: 3524 | J635: 6520.5 | K635: 6520.5
A636: 4743 | B636: 6935820080823 | C636: PAÑO ESCURRIDOR DE VAJILLAS | D636: BILBAO | E636: BLANQUERIA | F636: 5620 | G636: 5620 | H636: $ | I636: 2390 | J636: 4450.5 | K636: 4450.5
B637: 7798177030014 | C637: PROTECTOR BAÑO 50 MICRONES DUMOY | D637: BILBAO | E637: BLANQUERIA | F637: 3130 | G637: 3130 | H637: $ | I637: 4217 | J637: 2565.65 | K637: 2565.65
B638: 04445 | C638: REPASADOR ALGODON CON FLECOS | D638: BILBAO | E638: BLANQUERIA | F638: 950 | G638: 950 | H638: $ | I638: 4445 | J638: 701.5 | K638: 701.5
A639: 15465 | B639: BLA.BIL.02379 | C639: REPASADOR CARACAS | D639: BILBAO | E639: BLANQUERIA | F639: 950 | G639: 950 | H639: $ | I639: 2379 | J639: 724.5 | K639: 724.5
B640: BLA.BIL.02380 | C640: REPASADOR CORAZON | D640: BILBAO | E640: BLANQUERIA | F640: 1550 | G640: 1550 | H640: $ | I640: 2380 | J640: 1265 | K640: 1265
B641: 04446 | C641: REPASADOR ESCOCES SURTIDOS DISEÑOS | D641: BILBAO | E641: BLANQUERIA | F641: 1700 | G641: 1700 | H641: $ | I641: 4446 | J641: 1322.5 | K641: 1322.5
B642: 7794170054163 | C642: REPASADOR FANTASIA CUADROS 40X60 | D642: BILBAO | E642: BLANQUERIA | F642: 2660 | G642: 2660 | H642: $ | I642: 4062 | J642: 2185 | K642: 2185
B643: 8901281342563 | C643: REPASADOR INDU 100% ALGODON | D643: BILBAO | E643: BLANQUERIA | F643: 1880 | G643: 1880 | H643: $ | I643: 2381 | J643: 1536.4 | K643: 1536.4
B644: 04444 | C644: REPASADOR PICO DULCE | D644: BILBAO | E644: BLANQUERIA | F644: 1250 | G644: 1250 | H644: $ | I644: 4444 | J644: 1012 | K644: 1012
B645: 02386 | C645: SABANA 1 1/2 AJUST MICROFIBRA 70GRS | D645: BILBAO | E645: BLANQUERIA | F645: 4850 | G645: 4850 | H645: $ | I645: 2386 | J645: 3979 | K645: 3979
...
